
2022-08-03 18:01:44,863 INFO: errors [in C:\Users\USER\Desktop\Udacity\Fyyur\app.py:752]
2022-08-03 18:13:13,163 INFO: errors [in C:\Users\USER\Desktop\Udacity\Fyyur\app.py:751]
2022-08-03 18:13:13,278 INFO: errors [in C:\Users\USER\Desktop\Udacity\Fyyur\app.py:751]
2022-08-03 18:13:13,278 INFO: errors [in C:\Users\USER\Desktop\Udacity\Fyyur\app.py:751]
2022-08-03 18:30:17,819 INFO: errors [in C:\Users\USER\Desktop\Udacity\Fyyur\app.py:754]
2022-08-03 18:30:17,875 INFO: errors [in C:\Users\USER\Desktop\Udacity\Fyyur\app.py:754]
2022-08-03 18:30:17,875 INFO: errors [in C:\Users\USER\Desktop\Udacity\Fyyur\app.py:754]
2022-08-03 18:30:31,733 ERROR: Exception on / [GET] [in C:\Users\USER\anaconda3\envs\myflaskenv\lib\site-packages\flask\app.py:1457]
Traceback (most recent call last):
  File "C:\Users\USER\anaconda3\envs\myflaskenv\lib\site-packages\flask\app.py", line 2073, in wsgi_app
    response = self.full_dispatch_request()
  File "C:\Users\USER\anaconda3\envs\myflaskenv\lib\site-packages\flask\app.py", line 1518, in full_dispatch_request
    rv = self.handle_user_exception(e)
  File "C:\Users\USER\anaconda3\envs\myflaskenv\lib\site-packages\flask\app.py", line 1516, in full_dispatch_request
    rv = self.dispatch_request()
  File "C:\Users\USER\anaconda3\envs\myflaskenv\lib\site-packages\flask\app.py", line 1502, in dispatch_request
    return self.ensure_sync(self.view_functions[rule.endpoint])(**req.view_args)
  File "C:\Users\USER\Desktop\Udacity\Fyyur\app.py", line 69, in index
    recent_artists=db.query.Artist(Artist.name,Artist.imagelink).order_by(Artist.id).limit(10)
AttributeError: 'SQLAlchemy' object has no attribute 'query'
2022-08-03 18:30:31,733 ERROR: Exception on / [GET] [in C:\Users\USER\anaconda3\envs\myflaskenv\lib\site-packages\flask\app.py:1457]
Traceback (most recent call last):
  File "C:\Users\USER\anaconda3\envs\myflaskenv\lib\site-packages\flask\app.py", line 2073, in wsgi_app
    response = self.full_dispatch_request()
  File "C:\Users\USER\anaconda3\envs\myflaskenv\lib\site-packages\flask\app.py", line 1518, in full_dispatch_request
    rv = self.handle_user_exception(e)
  File "C:\Users\USER\anaconda3\envs\myflaskenv\lib\site-packages\flask\app.py", line 1516, in full_dispatch_request
    rv = self.dispatch_request()
  File "C:\Users\USER\anaconda3\envs\myflaskenv\lib\site-packages\flask\app.py", line 1502, in dispatch_request
    return self.ensure_sync(self.view_functions[rule.endpoint])(**req.view_args)
  File "C:\Users\USER\Desktop\Udacity\Fyyur\app.py", line 69, in index
    recent_artists=db.query.Artist(Artist.name,Artist.imagelink).order_by(Artist.id).limit(10)
AttributeError: 'SQLAlchemy' object has no attribute 'query'
2022-08-03 18:30:35,770 ERROR: Exception on / [GET] [in C:\Users\USER\anaconda3\envs\myflaskenv\lib\site-packages\flask\app.py:1457]
Traceback (most recent call last):
  File "C:\Users\USER\anaconda3\envs\myflaskenv\lib\site-packages\flask\app.py", line 2073, in wsgi_app
    response = self.full_dispatch_request()
  File "C:\Users\USER\anaconda3\envs\myflaskenv\lib\site-packages\flask\app.py", line 1518, in full_dispatch_request
    rv = self.handle_user_exception(e)
  File "C:\Users\USER\anaconda3\envs\myflaskenv\lib\site-packages\flask\app.py", line 1516, in full_dispatch_request
    rv = self.dispatch_request()
  File "C:\Users\USER\anaconda3\envs\myflaskenv\lib\site-packages\flask\app.py", line 1502, in dispatch_request
    return self.ensure_sync(self.view_functions[rule.endpoint])(**req.view_args)
  File "C:\Users\USER\Desktop\Udacity\Fyyur\app.py", line 69, in index
    recent_artists=db.query.Artist(Artist.name,Artist.imagelink).order_by(Artist.id).limit(10)
AttributeError: 'SQLAlchemy' object has no attribute 'query'
2022-08-03 18:30:35,770 ERROR: Exception on / [GET] [in C:\Users\USER\anaconda3\envs\myflaskenv\lib\site-packages\flask\app.py:1457]
Traceback (most recent call last):
  File "C:\Users\USER\anaconda3\envs\myflaskenv\lib\site-packages\flask\app.py", line 2073, in wsgi_app
    response = self.full_dispatch_request()
  File "C:\Users\USER\anaconda3\envs\myflaskenv\lib\site-packages\flask\app.py", line 1518, in full_dispatch_request
    rv = self.handle_user_exception(e)
  File "C:\Users\USER\anaconda3\envs\myflaskenv\lib\site-packages\flask\app.py", line 1516, in full_dispatch_request
    rv = self.dispatch_request()
  File "C:\Users\USER\anaconda3\envs\myflaskenv\lib\site-packages\flask\app.py", line 1502, in dispatch_request
    return self.ensure_sync(self.view_functions[rule.endpoint])(**req.view_args)
  File "C:\Users\USER\Desktop\Udacity\Fyyur\app.py", line 69, in index
    recent_artists=db.query.Artist(Artist.name,Artist.imagelink).order_by(Artist.id).limit(10)
AttributeError: 'SQLAlchemy' object has no attribute 'query'
2022-08-03 18:31:37,709 ERROR: Exception on / [GET] [in C:\Users\USER\anaconda3\envs\myflaskenv\lib\site-packages\flask\app.py:1457]
Traceback (most recent call last):
  File "C:\Users\USER\anaconda3\envs\myflaskenv\lib\site-packages\flask\app.py", line 2073, in wsgi_app
    response = self.full_dispatch_request()
  File "C:\Users\USER\anaconda3\envs\myflaskenv\lib\site-packages\flask\app.py", line 1518, in full_dispatch_request
    rv = self.handle_user_exception(e)
  File "C:\Users\USER\anaconda3\envs\myflaskenv\lib\site-packages\flask\app.py", line 1516, in full_dispatch_request
    rv = self.dispatch_request()
  File "C:\Users\USER\anaconda3\envs\myflaskenv\lib\site-packages\flask\app.py", line 1502, in dispatch_request
    return self.ensure_sync(self.view_functions[rule.endpoint])(**req.view_args)
  File "C:\Users\USER\Desktop\Udacity\Fyyur\app.py", line 69, in index
    recent_artists=db.session.query.Artist(Artist.name,Artist.imagelink).order_by(Artist.id).limit(10)
AttributeError: 'SQLAlchemy' object has no attribute 'query'
2022-08-03 18:31:37,709 ERROR: Exception on / [GET] [in C:\Users\USER\anaconda3\envs\myflaskenv\lib\site-packages\flask\app.py:1457]
Traceback (most recent call last):
  File "C:\Users\USER\anaconda3\envs\myflaskenv\lib\site-packages\flask\app.py", line 2073, in wsgi_app
    response = self.full_dispatch_request()
  File "C:\Users\USER\anaconda3\envs\myflaskenv\lib\site-packages\flask\app.py", line 1518, in full_dispatch_request
    rv = self.handle_user_exception(e)
  File "C:\Users\USER\anaconda3\envs\myflaskenv\lib\site-packages\flask\app.py", line 1516, in full_dispatch_request
    rv = self.dispatch_request()
  File "C:\Users\USER\anaconda3\envs\myflaskenv\lib\site-packages\flask\app.py", line 1502, in dispatch_request
    return self.ensure_sync(self.view_functions[rule.endpoint])(**req.view_args)
  File "C:\Users\USER\Desktop\Udacity\Fyyur\app.py", line 69, in index
    recent_artists=db.session.query.Artist(Artist.name,Artist.imagelink).order_by(Artist.id).limit(10)
AttributeError: 'SQLAlchemy' object has no attribute 'query'
2022-08-03 18:33:02,048 ERROR: Exception on / [GET] [in C:\Users\USER\anaconda3\envs\myflaskenv\lib\site-packages\flask\app.py:1457]
Traceback (most recent call last):
  File "C:\Users\USER\anaconda3\envs\myflaskenv\lib\site-packages\flask\app.py", line 2073, in wsgi_app
    response = self.full_dispatch_request()
  File "C:\Users\USER\anaconda3\envs\myflaskenv\lib\site-packages\flask\app.py", line 1518, in full_dispatch_request
    rv = self.handle_user_exception(e)
  File "C:\Users\USER\anaconda3\envs\myflaskenv\lib\site-packages\flask\app.py", line 1516, in full_dispatch_request
    rv = self.dispatch_request()
  File "C:\Users\USER\anaconda3\envs\myflaskenv\lib\site-packages\flask\app.py", line 1502, in dispatch_request
    return self.ensure_sync(self.view_functions[rule.endpoint])(**req.view_args)
  File "C:\Users\USER\Desktop\Udacity\Fyyur\app.py", line 69, in index
    recent_artists=db.session.query(Artist.name,Artist.imagelink).order_by(Artist.id).limit(10)
AttributeError: 'SQLAlchemy' object has no attribute 'query'
2022-08-03 18:33:02,048 ERROR: Exception on / [GET] [in C:\Users\USER\anaconda3\envs\myflaskenv\lib\site-packages\flask\app.py:1457]
Traceback (most recent call last):
  File "C:\Users\USER\anaconda3\envs\myflaskenv\lib\site-packages\flask\app.py", line 2073, in wsgi_app
    response = self.full_dispatch_request()
  File "C:\Users\USER\anaconda3\envs\myflaskenv\lib\site-packages\flask\app.py", line 1518, in full_dispatch_request
    rv = self.handle_user_exception(e)
  File "C:\Users\USER\anaconda3\envs\myflaskenv\lib\site-packages\flask\app.py", line 1516, in full_dispatch_request
    rv = self.dispatch_request()
  File "C:\Users\USER\anaconda3\envs\myflaskenv\lib\site-packages\flask\app.py", line 1502, in dispatch_request
    return self.ensure_sync(self.view_functions[rule.endpoint])(**req.view_args)
  File "C:\Users\USER\Desktop\Udacity\Fyyur\app.py", line 69, in index
    recent_artists=db.session.query(Artist.name,Artist.imagelink).order_by(Artist.id).limit(10)
AttributeError: 'SQLAlchemy' object has no attribute 'query'
2022-08-03 18:35:36,933 ERROR: Exception on / [GET] [in C:\Users\USER\anaconda3\envs\myflaskenv\lib\site-packages\flask\app.py:1457]
Traceback (most recent call last):
  File "C:\Users\USER\anaconda3\envs\myflaskenv\lib\site-packages\flask\app.py", line 2073, in wsgi_app
    response = self.full_dispatch_request()
  File "C:\Users\USER\anaconda3\envs\myflaskenv\lib\site-packages\flask\app.py", line 1518, in full_dispatch_request
    rv = self.handle_user_exception(e)
  File "C:\Users\USER\anaconda3\envs\myflaskenv\lib\site-packages\flask\app.py", line 1516, in full_dispatch_request
    rv = self.dispatch_request()
  File "C:\Users\USER\anaconda3\envs\myflaskenv\lib\site-packages\flask\app.py", line 1502, in dispatch_request
    return self.ensure_sync(self.view_functions[rule.endpoint])(**req.view_args)
  File "C:\Users\USER\Desktop\Udacity\Fyyur\app.py", line 69, in index
    recent_artists=db.session.query(Artist.name,Artist.image_link).order_by(Artist.id).limit(10)
AttributeError: 'SQLAlchemy' object has no attribute 'query'
2022-08-03 18:35:36,933 ERROR: Exception on / [GET] [in C:\Users\USER\anaconda3\envs\myflaskenv\lib\site-packages\flask\app.py:1457]
Traceback (most recent call last):
  File "C:\Users\USER\anaconda3\envs\myflaskenv\lib\site-packages\flask\app.py", line 2073, in wsgi_app
    response = self.full_dispatch_request()
  File "C:\Users\USER\anaconda3\envs\myflaskenv\lib\site-packages\flask\app.py", line 1518, in full_dispatch_request
    rv = self.handle_user_exception(e)
  File "C:\Users\USER\anaconda3\envs\myflaskenv\lib\site-packages\flask\app.py", line 1516, in full_dispatch_request
    rv = self.dispatch_request()
  File "C:\Users\USER\anaconda3\envs\myflaskenv\lib\site-packages\flask\app.py", line 1502, in dispatch_request
    return self.ensure_sync(self.view_functions[rule.endpoint])(**req.view_args)
  File "C:\Users\USER\Desktop\Udacity\Fyyur\app.py", line 69, in index
    recent_artists=db.session.query(Artist.name,Artist.image_link).order_by(Artist.id).limit(10)
AttributeError: 'SQLAlchemy' object has no attribute 'query'
2022-08-03 18:37:06,478 ERROR: Exception on / [GET] [in C:\Users\USER\anaconda3\envs\myflaskenv\lib\site-packages\flask\app.py:1457]
Traceback (most recent call last):
  File "C:\Users\USER\anaconda3\envs\myflaskenv\lib\site-packages\flask\app.py", line 2073, in wsgi_app
    response = self.full_dispatch_request()
  File "C:\Users\USER\anaconda3\envs\myflaskenv\lib\site-packages\flask\app.py", line 1518, in full_dispatch_request
    rv = self.handle_user_exception(e)
  File "C:\Users\USER\anaconda3\envs\myflaskenv\lib\site-packages\flask\app.py", line 1516, in full_dispatch_request
    rv = self.dispatch_request()
  File "C:\Users\USER\anaconda3\envs\myflaskenv\lib\site-packages\flask\app.py", line 1502, in dispatch_request
    return self.ensure_sync(self.view_functions[rule.endpoint])(**req.view_args)
  File "C:\Users\USER\Desktop\Udacity\Fyyur\app.py", line 69, in index
    #recent_artists=db.session.query(Artist.name,Artist.image_link).order_by(Artist.id).limit(10)
AttributeError: 'SQLAlchemy' object has no attribute 'query'
2022-08-03 18:37:06,478 ERROR: Exception on / [GET] [in C:\Users\USER\anaconda3\envs\myflaskenv\lib\site-packages\flask\app.py:1457]
Traceback (most recent call last):
  File "C:\Users\USER\anaconda3\envs\myflaskenv\lib\site-packages\flask\app.py", line 2073, in wsgi_app
    response = self.full_dispatch_request()
  File "C:\Users\USER\anaconda3\envs\myflaskenv\lib\site-packages\flask\app.py", line 1518, in full_dispatch_request
    rv = self.handle_user_exception(e)
  File "C:\Users\USER\anaconda3\envs\myflaskenv\lib\site-packages\flask\app.py", line 1516, in full_dispatch_request
    rv = self.dispatch_request()
  File "C:\Users\USER\anaconda3\envs\myflaskenv\lib\site-packages\flask\app.py", line 1502, in dispatch_request
    return self.ensure_sync(self.view_functions[rule.endpoint])(**req.view_args)
  File "C:\Users\USER\Desktop\Udacity\Fyyur\app.py", line 69, in index
    #recent_artists=db.session.query(Artist.name,Artist.image_link).order_by(Artist.id).limit(10)
AttributeError: 'SQLAlchemy' object has no attribute 'query'
2022-08-03 18:38:39,906 INFO: errors [in C:\Users\USER\Desktop\Udacity\Fyyur\app.py:755]
2022-08-03 18:38:39,971 INFO: errors [in C:\Users\USER\Desktop\Udacity\Fyyur\app.py:755]
2022-08-03 18:38:39,971 INFO: errors [in C:\Users\USER\Desktop\Udacity\Fyyur\app.py:755]
2022-08-03 18:43:22,772 INFO: errors [in C:\Users\USER\Desktop\Udacity\Fyyur\app.py:755]
2022-08-03 18:43:22,856 INFO: errors [in C:\Users\USER\Desktop\Udacity\Fyyur\app.py:755]
2022-08-03 18:43:22,856 INFO: errors [in C:\Users\USER\Desktop\Udacity\Fyyur\app.py:755]
2022-08-03 18:45:20,889 INFO: errors [in C:\Users\USER\Desktop\Udacity\Fyyur\app.py:755]
2022-08-03 18:45:20,957 INFO: errors [in C:\Users\USER\Desktop\Udacity\Fyyur\app.py:755]
2022-08-03 18:45:20,957 INFO: errors [in C:\Users\USER\Desktop\Udacity\Fyyur\app.py:755]
2022-08-03 18:45:24,622 INFO: errors [in C:\Users\USER\Desktop\Udacity\Fyyur\app.py:755]
2022-08-03 18:45:24,684 INFO: errors [in C:\Users\USER\Desktop\Udacity\Fyyur\app.py:755]
2022-08-03 18:45:24,684 INFO: errors [in C:\Users\USER\Desktop\Udacity\Fyyur\app.py:755]
2022-08-03 18:46:17,871 INFO: errors [in C:\Users\USER\Desktop\Udacity\Fyyur\app.py:755]
2022-08-03 18:46:17,940 INFO: errors [in C:\Users\USER\Desktop\Udacity\Fyyur\app.py:755]
2022-08-03 18:46:17,940 INFO: errors [in C:\Users\USER\Desktop\Udacity\Fyyur\app.py:755]
2022-08-03 18:46:45,363 INFO: errors [in C:\Users\USER\Desktop\Udacity\Fyyur\app.py:755]
2022-08-03 18:46:45,509 INFO: errors [in C:\Users\USER\Desktop\Udacity\Fyyur\app.py:755]
2022-08-03 18:46:45,509 INFO: errors [in C:\Users\USER\Desktop\Udacity\Fyyur\app.py:755]
2022-08-03 18:47:47,113 INFO: errors [in C:\Users\USER\Desktop\Udacity\Fyyur\app.py:755]
2022-08-03 18:47:47,166 INFO: errors [in C:\Users\USER\Desktop\Udacity\Fyyur\app.py:755]
2022-08-03 18:47:47,166 INFO: errors [in C:\Users\USER\Desktop\Udacity\Fyyur\app.py:755]
2022-08-03 18:48:48,111 INFO: errors [in C:\Users\USER\Desktop\Udacity\Fyyur\app.py:755]
2022-08-03 18:48:48,205 INFO: errors [in C:\Users\USER\Desktop\Udacity\Fyyur\app.py:755]
2022-08-03 18:48:48,205 INFO: errors [in C:\Users\USER\Desktop\Udacity\Fyyur\app.py:755]
2022-08-03 18:58:41,772 INFO: errors [in C:\Users\USER\Desktop\Udacity\Fyyur\app.py:755]
2022-08-03 18:58:41,857 INFO: errors [in C:\Users\USER\Desktop\Udacity\Fyyur\app.py:755]
2022-08-03 18:58:41,857 INFO: errors [in C:\Users\USER\Desktop\Udacity\Fyyur\app.py:755]
2022-08-03 18:58:47,856 INFO: errors [in C:\Users\USER\Desktop\Udacity\Fyyur\app.py:755]
2022-08-03 18:58:47,907 INFO: errors [in C:\Users\USER\Desktop\Udacity\Fyyur\app.py:755]
2022-08-03 18:58:47,907 INFO: errors [in C:\Users\USER\Desktop\Udacity\Fyyur\app.py:755]
